<?xml version="1.0"?>
<!--

Without ros2:

  0. Start the simulation:

    gz sim sailboat_model.sdf

  1. Move the rudder in radians:

    gz topic -t /rudder -m gz.msgs.Double -p 'data: .61'
    
  1a. View rudder position:

    gz topic -e -t /world/sailboat_model/model/my_ship/joint_state

  2. Set wind:

    gz topic -t /wind -m gz.msgs.Vector3d -p "x: 3, y: 3, z: 0"
  
  3. Set max sail angle in degrees:

   gz topic -t /sail_limit -m gz.msgs.Double -p 'data: 45'

With ros2: TODO: UPDATE

  0. Start the simulation (in ../launch/):

    ros2 launch motorboat_simulation.launch.py

  1. Move the rudder:

    ros2 topic pub /rudder std_msgs/msg/Float64 'data: .61'
  
-->

<sdf version="1.7">
  <world name="sailboat_model">

    <scene>
      <ambient>0.0 1.0 1.0</ambient>
      <background>0.0 0.7 0.8</background>

      <grid>false</grid>
    </scene>

    <light type="directional" name="sun">
      <cast_shadows>true</cast_shadows>
      <pose>0 0 10 0 0 0</pose>
      <diffuse>1 1 1 1</diffuse>
      <specular>0.5 0.5 0.5 1</specular>
      <attenuation>
        <range>1000</range>
        <constant>0.9</constant>
        <linear>0.01</linear>
        <quadratic>0.001</quadratic>
      </attenuation>
      <direction>-0.5 0.1 -0.9</direction>
    </light>

    <spherical_coordinates>
      <surface_model>EARTH_WGS84</surface_model>
      <world_frame_orientation>ENU</world_frame_orientation>
      <latitude_deg>0</latitude_deg>
      <longitude_deg>0</longitude_deg>
      <elevation>0</elevation>
      <heading_deg>0</heading_deg>
    </spherical_coordinates>

    <plugin
      filename="gz-sim-physics-system"
      name="gz::sim::systems::Physics">
    </plugin>

    <plugin
      filename="gz-sim-buoyancy-system"
      name="gz::sim::systems::Buoyancy">
      <graded_buoyancy>
        <default_density>1025</default_density>
        <density_change>
          <above_depth>0</above_depth>
          <density>1.125</density>
        </density_change>
      </graded_buoyancy>
    </plugin>

    <plugin
      filename="gz-sim-user-commands-system"
      name="gz::sim::systems::UserCommands">
    </plugin>

    <plugin
      filename="gz-sim-scene-broadcaster-system"
      name="gz::sim::systems::SceneBroadcaster">
    </plugin>

    <plugin
      filename="gz-sim-sensors-system"
      name="gz::sim::systems::Sensors">
    </plugin>

    <plugin
      filename="gz-sim-navsat-system"
      name="gz::sim::systems::NavSat">
    </plugin>

    <gui fullscreen="0">
      <!-- 3D scene -->
      <plugin filename="MinimalScene" name="3D View">
        <gz-gui>
          <title>3D View</title>
          <property type="bool" key="showTitleBar">false</property>
          <property type="string" key="state">docked</property>
        </gz-gui>
        <engine>ogre2</engine>
        <scene>scene</scene>
        <ambient_light>0.4 0.4 0.4</ambient_light>
        <background_color>0.8 0.8 0.8</background_color>
        <!-- looking at robot -->
        <camera_pose>0 6 6 0 0.5 -1.57</camera_pose>
        <camera_clip>
          <!-- ortho view needs low near clip -->
          <!-- but a very low near clip messes orbit's far clip ?! -->
          <near>0.1</near>
          <!-- See 3000 km away -->
          <far>3000000</far>
        </camera_clip>
      </plugin>
      <!-- Plugins that add functionality to the scene -->
      <plugin filename="EntityContextMenuPlugin" name="Entity context menu">
        <gz-gui>
          <property key="state" type="string">floating</property>
          <property key="width" type="double">5</property>
          <property key="height" type="double">5</property>
          <property key="showTitleBar" type="bool">false</property>
        </gz-gui>
      </plugin>
      <plugin filename="GzSceneManager" name="Scene Manager">
        <gz-gui>
          <anchors target="3D View">
            <line own="right" target="right" />
            <line own="top" target="top" />
          </anchors>
          <property key="resizable" type="bool">false</property>
          <property key="width" type="double">5</property>
          <property key="height" type="double">5</property>
          <property key="state" type="string">floating</property>
          <property key="showTitleBar" type="bool">false</property>
        </gz-gui>
      </plugin>
      <plugin filename="InteractiveViewControl" name="Interactive view control">
        <gz-gui>
          <anchors target="3D View">
            <line own="right" target="right" />
            <line own="top" target="top" />
          </anchors>
          <property key="resizable" type="bool">false</property>
          <property key="width" type="double">5</property>
          <property key="height" type="double">5</property>
          <property key="state" type="string">floating</property>
          <property key="showTitleBar" type="bool">false</property>
        </gz-gui>
      </plugin>
      <plugin filename="CameraTracking" name="Camera Tracking">
        <gz-gui>
          <anchors target="3D View">
            <line own="right" target="right" />
            <line own="top" target="top" />
          </anchors>
          <property key="resizable" type="bool">false</property>
          <property key="width" type="double">5</property>
          <property key="height" type="double">5</property>
          <property key="state" type="string">floating</property>
          <property key="showTitleBar" type="bool">false</property>
        </gz-gui>
      </plugin>
      <!-- World control -->
      <plugin filename="WorldControl" name="World control">
        <gz-gui>
          <title>World control</title>
          <property type="bool" key="showTitleBar">false</property>
          <property type="bool" key="resizable">false</property>
          <property type="double" key="height">72</property>
          <property type="double" key="width">121</property>
          <property type="double" key="z">1</property>
          <property type="string" key="state">floating</property>
          <anchors target="3D View">
            <line own="left" target="left" />
            <line own="bottom" target="bottom" />
          </anchors>
        </gz-gui>
        <play_pause>true</play_pause>
        <step>true</step>
        <start_paused>false</start_paused>
      </plugin>
      <!-- World statistics -->
      <plugin filename="GridConfig" name="Grid config">
        <gz-gui>
          <property type="string" key="state">docked_collapsed</property>
        </gz-gui>
        <insert>
          <!-- 0.1 km x 0.1 km -->
          <cell_count>100</cell_count>
          <vertical_cell_count>0</vertical_cell_count>
          <!-- 1 m -->
          <cell_length>1</cell_length>
          <pose>0 0 0 0 0 0</pose>
          <color>0.5 0.5 0.5 1</color>
        </insert>
      </plugin>
    </gui>

    <!-- This invisible plane helps with orbiting the camera, especially at large scales -->
    <model name="horizontal_plane">
      <static>true</static>
      <link name="link">
        <visual name="visual">
          <geometry>
            <plane>
              <normal>0 0 1</normal>
              <!-- 300 km x 300 km -->
              <size>300000 300000</size>
            </plane>
          </geometry>
          <transparency>1.0</transparency>
        </visual>
      </link>
    </model>


    <!-- Physics parameters -->
    <physics name="1ms" type="ode">
      <max_step_size>0.02</max_step_size>
      <real_time_factor>1</real_time_factor>
    </physics>

    <!-- Model to load -->
    <model name="my_ship">
      <link name='base_link'>
        <sensor name="navsat" type="navsat">
          <always_on>1</always_on>
          <update_rate>50</update_rate>
          <topic>navsat</topic>
        </sensor>
      </link>

      <plugin
        filename="gz-sim-odometry-publisher-system"
        name="gz::sim::systems::OdometryPublisher">
        <odom_topic>odometry</odom_topic>
      </plugin>

      <link name='left_front_link'>
        <pose>0.375 0.146175 0 0 0 0</pose>

        <inertial>
          <mass>11.34</mass>
          <inertia>
            <ixx>0.09603967727</ixx>
            <ixy>0</ixy>
            <ixz>0</ixz>
            <iyy>0.54683442351</iyy>
            <iyz>0</iyz>
            <izz>0.61233025376</izz>
          </inertia>
        </inertial>

        <collision name='collision'>
          <geometry>
            <box>
              <size>0.75 0.29235 0.127125</size>
            </box>
          </geometry>
        </collision>

        <visual name='visual'>
          <geometry>
            <box>
              <size>0.75 0.29235 0.127125</size>
            </box>
          </geometry>
        </visual>
      </link>

      <link name='right_front_link'>
        <pose>0.375 -0.146175 0 0 0 0</pose>

        <inertial>
          <mass>11.34</mass>
          <inertia>
            <ixx>0.09603967727</ixx>
            <ixy>0</ixy>
            <ixz>0</ixz>
            <iyy>0.54683442351</iyy>
            <iyz>0</iyz>
            <izz>0.61233025376</izz>
          </inertia>
        </inertial>

        <collision name='collision'>
          <geometry>
            <box>
              <size>0.75 0.29235 0.127125</size>
            </box>
          </geometry>
        </collision>

        <visual name='visual'>
          <geometry>
            <box>
              <size>0.75 0.29235 0.127125</size>
            </box>
          </geometry>
        </visual>
      </link>

      <link name='right_back_link'>
        <pose>-0.375 -0.146175 0 0 0 0</pose>

        <inertial>
          <mass>11.34</mass>
          <inertia>
            <ixx>0.09603967727</ixx>
            <ixy>0</ixy>
            <ixz>0</ixz>
            <iyy>0.54683442351</iyy>
            <iyz>0</iyz>
            <izz>0.61233025376</izz>
          </inertia>
        </inertial>

        <collision name='collision'>
          <geometry>
            <box>
              <size>0.75 0.29235 0.127125</size>
            </box>
          </geometry>
        </collision>

        <visual name='visual'>
          <geometry>
            <box>
              <size>0.75 0.29235 0.127125</size>
            </box>
          </geometry>
        </visual>
      </link>

      <link name='left_back_link'>
        <pose>-0.375 0.146175 0 0 0 0</pose>

        <inertial>
          <mass>11.34</mass>
          <inertia>
            <ixx>0.09603967727</ixx>
            <ixy>0</ixy>
            <ixz>0</ixz>
            <iyy>0.54683442351</iyy>
            <iyz>0</iyz>
            <izz>0.61233025376</izz>
          </inertia>
        </inertial>

        <collision name='collision'>
          <geometry>
            <box>
              <size>0.75 0.29235 0.127125</size>
            </box>
          </geometry>
        </collision>

        <visual name='visual'>
          <geometry>
            <box>
              <size>0.75 0.29235 0.127125</size>
            </box>
          </geometry>
        </visual>
      </link>

      <link name='keel_connector_link'>
        <pose>0 0 -0.502125 0 0 0</pose>

        <inertial>
          <mass>1.20958</mass>
          <inertia>
            <ixx>0.31020617154</ixx>
            <ixy>0</ixy>
            <ixz>0</ixz>
            <iyy>0.31020617154</iyy>
            <iyz>0</iyz>
            <izz>0.00002015966</izz>
          </inertia>
        </inertial>

        <collision name='collision'>
          <geometry>
            <box>
              <size>0.01 0.01 0.877125</size>
            </box>
          </geometry>
        </collision>

        <visual name='visual'>
          <geometry>
            <box>
              <size>0.01 0.01 0.877125</size>
            </box>
          </geometry>
        </visual>
      </link>

      <link name='keel_link'>
        <pose>0 0 -0.989753205 0 0 0</pose>

        <inertial>
          <mass>18.14368</mass>
          <inertia>
            <ixx>0.02912</ixx>
            <ixy>0</ixy>
            <ixz>0</ixz>
            <iyy>0.0728</iyy>
            <iyz>0</iyz>
            <izz>0.0728</izz>
          </inertia>
        </inertial>

        <collision name='collision'>
          <geometry>
            <box>
              <size>0.196263 0.09813141 0.09813141</size>
            </box>
          </geometry>
        </collision>

        <visual name='visual'>
          <geometry>
            <box>
              <size>0.196263 0.09813141 0.09813141</size>
            </box>
          </geometry>
        </visual>
      </link>

      <link name='mast_link'>
        <pose>0 0 0.8763 0 0 0</pose>

        <inertial>
          <mass>1.2</mass>
          <inertia>
            <ixx>0.307348176</ixx>
            <ixy>0</ixy>
            <ixz>0</ixz>
            <iyy>0.307348176</iyy>
            <iyz>0</iyz>
            <izz>0.000375</izz>
          </inertia>
        </inertial>

        <collision name='collision'>
          <geometry>
            <cylinder>
              <radius>.025</radius>
              <length>1.7526</length>
            </cylinder>
          </geometry>
        </collision>

        <visual name='visual'>
          <geometry>
            <cylinder>
              <radius>.025</radius>
              <length>1.7526</length>
            </cylinder>
          </geometry>
        </visual>
      </link>

      <link name='sail_rotator_link'>
        <pose>0 0 0 0 0 0</pose>
      </link>

      <link name='jib_rotator_link'>
        <pose>.5834 0 .4 0 0 0</pose>
      </link>

      <link name='boom_link'>
        <pose>-.5 0 .375 0 0 0</pose>

        <inertial>
          <mass>1</mass>
          <inertia>
            <ixx>0.08349</ixx>
            <ixy>0</ixy>
            <ixz>0</ixz>
            <iyy>0.08349</iyy>
            <iyz>0</iyz>
            <izz>0.0003125</izz>
          </inertia>
        </inertial>

        <collision name='collision'>
          <pose>0 0 0 0 1.57079632679 0</pose>
          <geometry>
            <cylinder>
              <radius>0.025</radius>
              <length>1</length>
            </cylinder>
          </geometry>
        </collision>

        <visual name='visual'>
          <pose>0 0 0 0 1.57079632679 0</pose>
          <geometry>
            <cylinder>
              <radius>0.025</radius>
              <length>1</length>
            </cylinder>
          </geometry>
        </visual>
      </link>

      <link name='sail_link'>
        <pose>-.025 0 0.4 0 0 0</pose>

        <inertial>
          <pose>-0.33033 0 0.45733 0 0 0</pose>
          <mass>0.5</mass>
          <inertia>
            <ixx>0.15687</ixx>
            <ixy>0.00008</ixy>
            <ixz>0.05665</ixz>
            <iyy>0.23871</iyy>
            <iyz>0.00011</iyz>
            <izz>0.08185</izz>
          </inertia>
        </inertial>

        <collision name='collision'>
          <pose>0 0 0 1.57079632679 0 0</pose>
          <geometry>
            <polyline>
              <point>0 0</point>
              <point>0 1.372</point>
              <point>-0.991 0</point>
              <height>.001</height>
            </polyline>
          </geometry>
        </collision>

        <visual name='visual'>
          <pose>0 0 0 1.57079632679 0 0</pose>
          <geometry>
            <polyline>
              <point>0 0</point>
              <point>0 1.372</point>
              <point>-0.991 0</point>
              <height>.001</height>
            </polyline>
          </geometry>
        </visual>
      </link>

      <link name='jib_link'>
        <pose>.03 0 0.4 0 0 0</pose>

        <inertial>
          <pose>-0.33033 0 0.45733 0 0 0</pose>
          <mass>0.25908</mass>
          <inertia>
            <ixx>0.07533</ixx>
            <ixy>-0.00002</ixy>
            <ixz>0.01521</ixz>
            <iyy>0.08761</iyy>
            <iyz>0.00006</iyz>
            <izz>0.01229</izz>
          </inertia>
        </inertial>

        <collision name='collision'>
          <pose>0 0 0 1.57079632679 0 0</pose>
          <geometry>
            <polyline>
              <point>0 0</point>
              <point>0 1.3208</point>
              <point>0.5334 0</point>
              <height>.001</height>
            </polyline>
          </geometry>
        </collision>

        <visual name='visual'>
          <pose>0 0 0 1.57079632679 0 0</pose>
          <geometry>
            <polyline>
              <point>0 0</point>
              <point>0 1.3208</point>
              <point>0.5334 0</point>
              <height>.001</height>
            </polyline>
          </geometry>
        </visual>
      </link>


      <!-- Arrow link for showing wind -->
       <link name='arrow_link'>
        <pose>0 0 1.8 0 0 0</pose>

        <visual name='visual'>
          <pose>0 0 0 0 1.57079632679 0</pose>
          <geometry>
            <cone>
              <radius>0.05</radius>
              <length>.5</length>
            </cone>
          </geometry>
          <material>
            <diffuse>0.8 0 0 1</diffuse>
          </material>
        </visual>

        <gravity>0</gravity>
      </link>

      <!-- Main body joints -->
      <joint name="left_front_joint" type="fixed">
        <parent>base_link</parent>
        <child>left_front_link</child>
      </joint>

      <joint name="right_front_joint" type="fixed">
        <parent>base_link</parent>
        <child>right_front_link</child>
      </joint>

      <joint name="right_back_joint" type="fixed">
        <parent>base_link</parent>
        <child>right_back_link</child>
      </joint>

      <joint name="left_back_joint" type="fixed">
        <parent>base_link</parent>
        <child>left_back_link</child>
      </joint>

      <joint name="keel_connector_joint" type="fixed">
        <parent>base_link</parent>
        <child>keel_connector_link</child>
      </joint>

      <joint name="keel_joint" type="fixed">
        <parent>keel_connector_link</parent>
        <child>keel_link</child>
      </joint>

      <joint name="sail_rotator_joint" type="revolute">
        <axis>
          <xyz>0 0 1</xyz>
          <limit>
            <lower>-1</lower>
            <upper>1</upper>
          </limit>
          <dynamics>
            <damping>1</damping>
          </dynamics>
        </axis>
        
        <parent>base_link</parent>
        <child>sail_rotator_link</child>
      </joint>
      
      <joint name="jib_rotator_joint" type="revolute">
        <axis>
          <xyz>-0.5534 0 1.3208</xyz>
          <limit>
            <lower>-.6</lower>
            <upper>.6</upper>
          </limit>
          <dynamics>
            <damping>1</damping>
          </dynamics>
        </axis>

        <parent>base_link</parent>
        <child>jib_rotator_link</child>
      </joint>

      <joint name="jib_joint" type="fixed">
        <parent>jib_rotator_link</parent>
        <child>jib_link</child>
      </joint>

      <joint name="mast_joint" type="fixed">
        <parent>base_link</parent>
        <child>mast_link</child>
      </joint>

      <joint name="boom_joint" type="fixed">
        <parent>sail_rotator_link</parent>
        <child>boom_link</child>
      </joint>

      <joint name="sail_joint" type="fixed">
        <parent>boom_link</parent>
        <child>sail_link</child>
      </joint>

      <joint name="arrow_joint" type="revolute">
        <parent>base_link</parent>
        <child>arrow_link</child>

        <axis>
          <xyz>0 0 1</xyz>
          <limit>
            <lower>-1e+12</lower>
            <upper>1e+12</upper>
          </limit>
        </axis>
      </joint>
      

      <!-- Rudder -->
      
      <link name='rudder_link'>
        <pose>-.75 0 -0.15425 0 0 0</pose>

        <inertial>
          <mass>1</mass>
          <inertia>
            <ixx>0.00282940576</ixx>
            <ixy>0</ixy>
            <ixz>0</ixz>
            <iyy>0.00401459983</iyy>
            <iyz>0</iyz>
            <izz>0.00139589893</izz>
          </inertia>
        </inertial>

        <collision name='collision'>
          <geometry>
            <box>
              <size>0.124445 0.035556 0.1808</size>
            </box>
          </geometry>
        </collision>

        <visual name='visual'>
          <geometry>
            <box>
              <size>0.124445 0.035556 0.1808</size>
            </box>
          </geometry>
        </visual>
      </link>

      <joint name="rudder_joint" type="revolute">
        <pose>0 0 0 0 0 0</pose>
        <parent>base_link</parent>
        <child>rudder_link</child>
        <axis>
          <xyz>0 0 1</xyz>
          <limit>
            <lower>-1e+12</lower>
            <upper>1e+12</upper>
          </limit>
          <dynamics>
            <damping>1</damping>
          </dynamics>
        </axis>
      </joint>

      <!-- Joint state publisher for the rudder -->
      <plugin
        filename="gz-sim-joint-state-publisher-system"
        name="gz::sim::systems::JointStatePublisher">
        <joint_name>rudder_joint</joint_name>
        <topic>rudder_angle</topic>
      </plugin>

      <!-- Joint state publisher for the sail -->
      <plugin
        filename="gz-sim-joint-state-publisher-system"
        name="gz::sim::systems::JointStatePublisher">
        <joint_name>sail_rotator_joint</joint_name>
        <topic>sail_angle</topic>
      </plugin>

      <plugin
        filename="gz-sim-pose-publisher-system"
        name="gz::sim::systems::PosePublisher">
        <publish_link_pose>true</publish_link_pose>
      </plugin>

      <plugin
        filename="gz-sim-joint-position-controller-system"
        name="gz::sim::systems::JointPositionController">
        <joint_name>rudder_joint</joint_name>
        <topic>rudder</topic>
      </plugin>

      <plugin filename="libRudderDynamics.so"
      name="rudder_dynamics::RudderDynamics">
        <link0>rudder_link</link0>
        <clmax>4.72</clmax>
        <cdmax>4.16</cdmax>
        <area>.0225</area>
        <fluid_density>1025</fluid_density>
        <forward>1 0 0</forward>
        <upward>0 1 0</upward>
      </plugin>

      <!-- Drag on the hull parts -->
      <!-- TODO: get clmax, cdmax for hull -->
      <plugin filename="libRudderDynamics.so"
      name="rudder_dynamics::RudderDynamics">
        <link0>left_front_link</link0>
        <link1>right_front_link</link1>
        <link2>left_back_link</link2>
        <link3>right_back_link</link3>
        <clmax>2</clmax>
        <cdmax>4</cdmax>
        <area>0.03716499375</area>
        <fluid_density>1025</fluid_density>
        <forward>1 0 0</forward>
        <upward>0 0 1</upward>
      </plugin>

      <!-- Sail dynamics plugin -->
      <!-- TODO: get values for clmax and cdmax (cl vs alpha and cd vs alpha curves) -->
      <plugin filename="libFoilDynamics.so"
      name="foil_dynamics::FoilDynamics">
        <link_name>sail_link</link_name>
        <clmax>1</clmax>
        <cdmax>1.5</cdmax>
        <cop>0.33033 0.45733 0</cop>
        <area>.75</area>
        <fluid_density>1.225</fluid_density>
        <forward>-1 0 0</forward>
        <upward>0 -1 0</upward>
      </plugin>

      <!-- Jib dynamics...? Might need its own plugin idk tbh -->
      <plugin filename="libFoilDynamics.so"
      name="foil_dynamics::FoilDynamics">
        <link_name>jib_link</link_name>
        <clmax>1</clmax>
        <cdmax>1.5</cdmax>
        <cop>0.18447 0.44027 0</cop>
        <area>.73</area>
        <fluid_density>1.225</fluid_density>
        <forward>-1 0 0</forward>
        <upward>0 -1 0</upward>
      </plugin>

      <!-- Sail rotation plugin -->
      <plugin filename="libSailLimits.so"
      name="sail_limits::SailLimits">
        <joint_name>sail_rotator_joint</joint_name>
      </plugin>

      <!-- Arrow rotation plugin -->
       <plugin filename="libWindArrow.so"
      name="wind_arrow::WindArrow">
        <joint_name>arrow_joint</joint_name>
        <base_link_name>base_link</base_link_name>
      </plugin>

      <!-- Hydrodynamics on the hull parts -->
      <plugin
        filename="gz-sim-hydrodynamics-system"
        name="gz::sim::systems::Hydrodynamics">
        <link_name>left_front_link</link_name>
        <xUabsU>-.6</xUabsU>
        <xU>-.6</xU>
        <yVabsV>-.6</yVabsV>
        <yV>-.6</yV>
        <zWabsW>-60</zWabsW>
        <zW>-60</zW>
        <kPabsP>-5</kPabsP>
        <kP>-5</kP>
        <mQabsQ>-5</mQabsQ>
        <mQ>-5</mQ>
        <nRabsR>-12</nRabsR>
        <nR>-12</nR>
      </plugin>
      <plugin
        filename="gz-sim-hydrodynamics-system"
        name="gz::sim::systems::Hydrodynamics">
        <link_name>right_front_link</link_name>
        <xUabsU>-.6</xUabsU>
        <xU>-.6</xU>
        <yVabsV>-.6</yVabsV>
        <yV>-.6</yV>
        <zWabsW>-60</zWabsW>
        <zW>-60</zW>
        <kPabsP>-5</kPabsP>
        <kP>-5</kP>
        <mQabsQ>-5</mQabsQ>
        <mQ>-5</mQ>
        <nRabsR>-12</nRabsR>
        <nR>-12</nR>
      </plugin>
      <plugin
        filename="gz-sim-hydrodynamics-system"
        name="gz::sim::systems::Hydrodynamics">
        <link_name>right_back_link</link_name>
        <xUabsU>-.6</xUabsU>
        <xU>-.6</xU>
        <yVabsV>-.6</yVabsV>
        <yV>-.6</yV>
        <zWabsW>-60</zWabsW>
        <zW>-60</zW>
        <kPabsP>-5</kPabsP>
        <kP>-5</kP>
        <mQabsQ>-5</mQabsQ>
        <mQ>-5</mQ>
        <nRabsR>-12</nRabsR>
        <nR>-12</nR>
      </plugin>
      <plugin
        filename="gz-sim-hydrodynamics-system"
        name="gz::sim::systems::Hydrodynamics">
        <link_name>left_back_link</link_name>
        <xUabsU>-.6</xUabsU>
        <xU>-.6</xU>
        <yVabsV>-.6</yVabsV>
        <yV>-.6</yV>
        <zWabsW>-60</zWabsW>
        <zW>-60</zW>
        <kPabsP>-5</kPabsP>
        <kP>-5</kP>
        <mQabsQ>-5</mQabsQ>
        <mQ>-5</mQ>
        <nRabsR>-12</nRabsR>
        <nR>-12</nR>
      </plugin>
      <plugin
        filename="gz-sim-hydrodynamics-system"
        name="gz::sim::systems::Hydrodynamics">
        <link_name>keel_connector_link</link_name>
        <xUabsU>-6</xUabsU>
        <xU>-6</xU>
        <yVabsV>-6</yVabsV>
        <yV>-6</yV>
        <zWabsW>-60</zWabsW>
        <zW>-60</zW>
        <kPabsP>-0.5</kPabsP>
        <kP>-0.5</kP>
        <mQabsQ>-5</mQabsQ>
        <mQ>-5</mQ>
        <nRabsR>-0.6</nRabsR>
        <nR>-0.6</nR>
      </plugin>
      <plugin
        filename="gz-sim-hydrodynamics-system"
        name="gz::sim::systems::Hydrodynamics">
        <link_name>keel_link</link_name>
        <xUabsU>-6</xUabsU>
        <xU>-6</xU>
        <yVabsV>-6</yVabsV>
        <yV>-6</yV>
        <zWabsW>-60</zWabsW>
        <zW>-60</zW>
        <kPabsP>-0.5</kPabsP>
        <kP>-0.5</kP>
        <mQabsQ>-5</mQabsQ>
        <mQ>-5</mQ>
        <nRabsR>-0.6</nRabsR>
        <nR>-0.6</nR>
      </plugin>
    </model>
  </world>
</sdf>